Workbook

Sheet __FDSCACHE__
B1: This sheet contains Factset binary data for use with this workbook's =FDS codes. Modifying the worksheet's contents may damage the workbook's =FDS functionality.

Sheet Assumptions
B2: IPO Assumptions
B3: ($ and shares in millions, except per share amounts) | F3: Value
B5: Filing range – low | F5: 20
B6: Filing range – high | F6: 22
B8: Primary shares issued | F8: 5.5
B9: Secondary shares sold | F9: 4.5
B11: Underwriting discount (%) | F11: 0.06
B12: IPO discount (%) | F12: 0.15
B14: Overallotment
B15: Overallotment ("Greenshoe") (%) | F15: 0.15
B16: Primary allocation (%) | F16: 1
B17: Exercise shoe? | F17: 1
B19: IPO fees & expenses
B20: SEC registration fee | F20: 0.03483
B21: FINRA Filing fee | F21: 0.0305
B22: Nasdaq listing fees and expenses | F22: 0.025
B23: Transfer agent and registrar fees and expenses | F23: 0.1
B24: Printing fees and expenses | F24: 0.7
B25: Legal fees and expenses | F25: 3
B26: Accounting fees and expenses | F26: 1.5
B27: Miscellaneous | F27: 0.11
B31: Issuer Assumptions
B32: ($ and shares in millions, except per share amounts) | F32: Value
B34: Class A common stock | F34: 20.3
B35: Class B common stock | F35: 26.1
B37: Options strike price | F37: 20
B38: Options outstanding | F38: 2.9
B40: Issuer 2013E earnings | F40: 70
B41: Issuer 2014E earnings | F41: 95

Sheet FDSO
B2: Fully Diluted Share Count ("FDSO") Matrix
B4: Options strike price | D4: =Assumptions!F37 -> 20
B5: Options outstanding | D5: =Assumptions!F38 -> 2.9
E7: Potential Range of IPO Prices
A8: 1 | B8: (shares in millions) | E8: 18 | F8: =E8+1 -> 19 | G8: =F8+1 -> 20 | H8: =G8+1 -> 21 | I8: =H8+1 -> 22 | J8: =I8+1 -> 23 | K8: =J8+1 -> 24
A9: =A8+1 -> 2
A10: =A9+1 -> 3 | B10: =Assumptions!B34 -> Class A common stock | E10: =Assumptions!F34 -> 20.3 | F10: =E10 -> 20.3 | G10: =F10 -> 20.3 | H10: =G10 -> 20.3 | I10: =H10 -> 20.3 | J10: =I10 -> 20.3 | K10: =J10 -> 20.3
A11: =A10+1 -> 4 | B11: =Assumptions!B35 -> Class B common stock | E11: =Assumptions!F35 -> 26.1 | F11: =E11 -> 26.1 | G11: =F11 -> 26.1 | H11: =G11 -> 26.1 | I11: =H11 -> 26.1 | J11: =I11 -> 26.1 | K11: =J11 -> 26.1
A12: =A11+1 -> 5 | B12: Total basic shares outstanding | E12: =SUM(E10:E11) -> 46.4 | F12: =SUM(F10:F11) -> 46.4 | G12: =SUM(G10:G11) -> 46.4 | H12: =SUM(H10:H11) -> 46.4 | I12: =SUM(I10:I11) -> 46.4 | J12: =SUM(J10:J11) -> 46.4 | K12: =SUM(K10:K11) -> 46.4
A13: =A12+1 -> 6 | B13: ( + ) Stock options | E13: =IF($D$4<E8,$D$5-$D$5*$D$4/E8,0) -> 0 | F13: =IF($D$4<F8,$D$5-$D$5*$D$4/F8,0) -> 0 | G13: =IF($D$4<G8,$D$5-$D$5*$D$4/G8,0) -> 0 | H13: =IF($D$4<H8,$D$5-$D$5*$D$4/H8,0) -> 0.13809524 | I13: =IF($D$4<I8,$D$5-$D$5*$D$4/I8,0) -> 0.26363636 | J13: =IF($D$4<J8,$D$5-$D$5*$D$4/J8,0) -> 0.37826087 | K13: =IF($D$4<K8,$D$5-$D$5*$D$4/K8,0) -> 0.48333333
A14: =A13+1 -> 7 | B14: Fully diluted shares outstanding | E14: =SUM(E12:E13) -> 46.4 | F14: =SUM(F12:F13) -> 46.4 | G14: =SUM(G12:G13) -> 46.4 | H14: =SUM(H12:H13) -> 46.538095 | I14: =SUM(I12:I13) -> 46.663636 | J14: =SUM(J12:J13) -> 46.778261 | K14: =SUM(K12:K13) -> 46.883333

Sheet IPO
B2: IPO Calculations
F3: Filing Range
B4: ($ and shares in millions, except per share amounts) | F4: Low | G4: Midpoint | H4: High
B6: Offering price per share | F6: =Assumptions!F5 -> 20 | G6: =AVERAGE(F6,H6) -> 21 | H6: =Assumptions!F6 -> 22
B8: Shares
B10: Shares offered
B11: Primary shares issued | F11: =Assumptions!$F8 -> 5.5 | G11: =Assumptions!$F8 -> 5.5 | H11: =Assumptions!$F8 -> 5.5
B12: Secondary shares sold | F12: =Assumptions!$F9 -> 4.5 | G12: =Assumptions!$F9 -> 4.5 | H12: =Assumptions!$F9 -> 4.5
B13: Base deal shares issued/sold | F13: =SUM(F11:F12) -> 10 | G13: =SUM(G11:G12) -> 10 | H13: =SUM(H11:H12) -> 10
B14: Overallotment – primary shares | F14: =F13*Assumptions!$F$15*Assumptions!$F$16*Assumptions!$F$17 -> 1.5 | G14: =G13*Assumptions!$F$15*Assumptions!$F$16*Assumptions!$F$17 -> 1.5 | H14: =H13*Assumptions!$F$15*Assumptions!$F$16*Assumptions!$F$17 -> 1.5
B15: Overallotment – secondary shares | F15: =F13*Assumptions!$F$15*(1-Assumptions!$F$16)*Assumptions!$F$17 -> 0 | G15: =G13*Assumptions!$F$15*(1-Assumptions!$F$16)*Assumptions!$F$17 -> 0 | H15: =H13*Assumptions!$F$15*(1-Assumptions!$F$16)*Assumptions!$F$17 -> 0
B16: Total overallotment | F16: =SUM(F14:F15) -> 1.5 | G16: =SUM(G14:G15) -> 1.5 | H16: =SUM(H14:H15) -> 1.5
B17: Total shares issued/sold | F17: =F16+F13 -> 11.5 | G17: =G16+G13 -> 11.5 | H17: =H16+H13 -> 11.5
B19: Pro forma shares
B20: Existing Issuer FDSO | F20: =HLOOKUP(F$6,FDSO!$E$8:$K$14,FDSO!$A$14,FALSE) -> 46.4 | G20: =HLOOKUP(G$6,FDSO!$E$8:$K$14,FDSO!$A$14,FALSE) -> 46.538095 | H20: =HLOOKUP(H$6,FDSO!$E$8:$K$14,FDSO!$A$14,FALSE) -> 46.663636
B21: ( + ) Primary shares issued | F21: =F11+F14 -> 7 | G21: =G11+G14 -> 7 | H21: =H11+H14 -> 7
B22: Pro forma Issuer FDSO | F22: =SUM(F20:F21) -> 53.4 | G22: =SUM(G20:G21) -> 53.538095 | H22: =SUM(H20:H21) -> 53.663636
B24: Offering Size
B26: Base deal | F26: =F13*F6 -> 200 | G26: =G13*G6 -> 210 | H26: =H13*H6 -> 220
B27: ( + ) Overallotment | F27: =F16*F6 -> 30 | G27: =G16*G6 -> 31.5 | H27: =H16*H6 -> 33
B28: Total offering size | F28: =SUM(F26:F27) -> 230 | G28: =SUM(G26:G27) -> 241.5 | H28: =SUM(H26:H27) -> 253
B30: IPO Discount & Fees
B32: Underwriting discount
B33: IPO price per share | F33: =F6 -> 20 | G33: =G6 -> 21 | H33: =H6 -> 22
B34: ="( – ) Underwriting discount ("&TEXT(Assumptions!F11,"0.0%")&")" -> ( – ) Underwriting discount (6.0%) | F34: =-Assumptions!$F$11*F33 -> -1.2 | G34: =-Assumptions!$F$11*G33 -> -1.26 | H34: =-Assumptions!$F$11*H33 -> -1.32
B35: Net IPO price per share | F35: =SUM(F33:F34) -> 18.8 | G35: =SUM(G33:G34) -> 19.74 | H35: =SUM(H33:H34) -> 20.68
B37: Offering expenses
B38: =Assumptions!B20 -> SEC registration fee | F38: =Assumptions!F20 -> 0.03483 | G38: =F38 -> 0.03483 | H38: =G38 -> 0.03483
B39: =Assumptions!B21 -> FINRA Filing fee | F39: =Assumptions!F21 -> 0.0305 | G39: =F39 -> 0.0305 | H39: =G39 -> 0.0305
B40: =Assumptions!B22 -> Nasdaq listing fees and expenses | F40: =Assumptions!F22 -> 0.025 | G40: =F40 -> 0.025 | H40: =G40 -> 0.025
B41: =Assumptions!B23 -> Transfer agent and registrar fees and expenses | F41: =Assumptions!F23 -> 0.1 | G41: =F41 -> 0.1 | H41: =G41 -> 0.1
B42: =Assumptions!B24 -> Printing fees and expenses | F42: =Assumptions!F24 -> 0.7 | G42: =F42 -> 0.7 | H42: =G42 -> 0.7
B43: =Assumptions!B25 -> Legal fees and expenses | F43: =Assumptions!F25 -> 3 | G43: =F43 -> 3 | H43: =G43 -> 3
B44: =Assumptions!B26 -> Accounting fees and expenses | F44: =Assumptions!F26 -> 1.5 | G44: =F44 -> 1.5 | H44: =G44 -> 1.5
B45: =Assumptions!B27 -> Miscellaneous | F45: =Assumptions!F27 -> 0.11 | G45: =F45 -> 0.11 | H45: =G45 -> 0.11
B46: Total expenses | F46: =SUM(F38:F45) -> 5.50033 | G46: =SUM(G38:G45) -> 5.50033 | H46: =SUM(H38:H45) -> 5.50033
B48: IPO Proceeds
B50: Gross primary proceeds | F50: =F33*F21 -> 140 | G50: =G33*G21 -> 147 | H50: =H33*H21 -> 154
B51: ( – ) Underwriting discount | F51: =F34*F21 -> -8.4 | G51: =G34*G21 -> -8.82 | H51: =H34*H21 -> -9.24
B52: ( – ) Expenses | F52: =-F46 -> -5.50033 | G52: =-G46 -> -5.50033 | H52: =-H46 -> -5.50033
...
